2024-06-13 16:34:42,601 ERROR Internal Server Error: / C:\Users\79895\PycharmProjects\NewsPortalProject\venv\lib\site-packages\django\utils\log.py (<class 'TypeError'>, TypeError("debug() missing 1 required positional argument: 'msg'"), <traceback object at 0x0000013033346240>)
Traceback (most recent call last):
  File "C:\Users\79895\PycharmProjects\NewsPortalProject\venv\lib\site-packages\django\core\handlers\exception.py", line 55, in inner
    response = get_response(request)
  File "C:\Users\79895\PycharmProjects\NewsPortalProject\venv\lib\site-packages\django\core\handlers\base.py", line 197, in _get_response
    response = wrapped_callback(request, *callback_args, **callback_kwargs)
  File "C:\Users\79895\PycharmProjects\NewsPortalProject\venv\lib\site-packages\django\views\generic\base.py", line 104, in view
    return self.dispatch(request, *args, **kwargs)
  File "C:\Users\79895\PycharmProjects\NewsPortalProject\venv\lib\site-packages\django\contrib\auth\mixins.py", line 73, in dispatch
    return super().dispatch(request, *args, **kwargs)
  File "C:\Users\79895\PycharmProjects\NewsPortalProject\venv\lib\site-packages\django\views\generic\base.py", line 143, in dispatch
    return handler(request, *args, **kwargs)
  File "C:\Users\79895\PycharmProjects\NewsPortalProject\venv\lib\site-packages\django\views\generic\list.py", line 154, in get
    self.object_list = self.get_queryset()
  File "C:\Users\79895\PycharmProjects\NewsPortalProject\news_portal\my_news_portal\views.py", line 28, in get_queryset
    logger.debug()
TypeError: debug() missing 1 required positional argument: 'msg'
2024-06-13 16:34:42,605 ERROR "GET / HTTP/1.1" 500 91726 C:\Users\79895\PycharmProjects\NewsPortalProject\venv\lib\site-packages\django\core\servers\basehttp.py None
2024-06-14 16:33:45,682 ERROR Internal Server Error: /sign/logout/ C:\Users\79895\PycharmProjects\NewsPortalProject\venv\lib\site-packages\django\utils\log.py (<class 'django.template.exceptions.TemplateDoesNotExist'>, TemplateDoesNotExist('main.html'), <traceback object at 0x000002965AC2E8C0>)
Traceback (most recent call last):
  File "C:\Users\79895\PycharmProjects\NewsPortalProject\venv\lib\site-packages\django\template\backends\django.py", line 61, in render
    return self.template.render(context)
  File "C:\Users\79895\PycharmProjects\NewsPortalProject\venv\lib\site-packages\django\template\base.py", line 175, in render
    return self._render(context)
  File "C:\Users\79895\PycharmProjects\NewsPortalProject\venv\lib\site-packages\django\template\base.py", line 167, in _render
    return self.nodelist.render(context)
  File "C:\Users\79895\PycharmProjects\NewsPortalProject\venv\lib\site-packages\django\template\base.py", line 1005, in render
    return SafeString("".join([node.render_annotated(context) for node in self]))
  File "C:\Users\79895\PycharmProjects\NewsPortalProject\venv\lib\site-packages\django\template\base.py", line 1005, in <listcomp>
    return SafeString("".join([node.render_annotated(context) for node in self]))
  File "C:\Users\79895\PycharmProjects\NewsPortalProject\venv\lib\site-packages\django\template\base.py", line 966, in render_annotated
    return self.render(context)
  File "C:\Users\79895\PycharmProjects\NewsPortalProject\venv\lib\site-packages\django\template\loader_tags.py", line 132, in render
    compiled_parent = self.get_parent(context)
  File "C:\Users\79895\PycharmProjects\NewsPortalProject\venv\lib\site-packages\django\template\loader_tags.py", line 129, in get_parent
    return self.find_template(parent, context)
  File "C:\Users\79895\PycharmProjects\NewsPortalProject\venv\lib\site-packages\django\template\loader_tags.py", line 107, in find_template
    template, origin = context.template.engine.find_template(
  File "C:\Users\79895\PycharmProjects\NewsPortalProject\venv\lib\site-packages\django\template\engine.py", line 161, in find_template
    raise TemplateDoesNotExist(name, tried=tried)
django.template.exceptions.TemplateDoesNotExist: main.html

The above exception was the direct cause of the following exception:

Traceback (most recent call last):
  File "C:\Users\79895\PycharmProjects\NewsPortalProject\venv\lib\site-packages\django\core\handlers\exception.py", line 55, in inner
    response = get_response(request)
  File "C:\Users\79895\PycharmProjects\NewsPortalProject\venv\lib\site-packages\django\core\handlers\base.py", line 220, in _get_response
    response = response.render()
  File "C:\Users\79895\PycharmProjects\NewsPortalProject\venv\lib\site-packages\django\template\response.py", line 114, in render
    self.content = self.rendered_content
  File "C:\Users\79895\PycharmProjects\NewsPortalProject\venv\lib\site-packages\django\template\response.py", line 92, in rendered_content
    return template.render(context, self._request)
  File "C:\Users\79895\PycharmProjects\NewsPortalProject\venv\lib\site-packages\django\template\backends\django.py", line 63, in render
    reraise(exc, self.backend)
  File "C:\Users\79895\PycharmProjects\NewsPortalProject\venv\lib\site-packages\django\template\backends\django.py", line 84, in reraise
    raise new from exc
django.template.exceptions.TemplateDoesNotExist: main.html
2024-06-14 16:33:45,706 ERROR "GET /sign/logout/ HTTP/1.1" 500 137042 C:\Users\79895\PycharmProjects\NewsPortalProject\venv\lib\site-packages\django\core\servers\basehttp.py None
